Workbook

Sheet Отчет о фин.рез.
A1: Наименование статей | B1: январь | C1: февраль | D1: март | E1: апрель | F1: май | G1: июнь | H1: июль | I1: август | J1: сентябрь | K1: октябрь | L1: ноябрь | M1: декабрь | N1: Итого | O1: Проверка
A2: Выручка, всего, в т.ч. | B2: =SUM(B3:B5) -> 0 | C2: =SUM(C3:C5) -> 0 | D2: =SUM(D3:D5) -> 5929.9 | E2: =SUM(E3:E5) -> 13713.2 | F2: =SUM(F3:F5) -> 15712.59 | G2: =SUM(G3:G5) -> 14253.351 | H2: =SUM(H3:H5) -> 0 | I2: =SUM(I3:I5) -> 0 | ... N2: =SUM(N3:N5) -> 49609.041 | O2: =+SUM($B2:$M2)-N2 -> 0
A3: зал | B3: 0 | D3: 5929.9 | E3: 13713.2 | F3: 15712.59 | G3: 14253.351 | N3: =SUM(B3:M3) -> 49609.041 | O3: =+SUM($B3:$M3)-N3 -> 0
A4: доставка | B4: 0 | N4: =SUM(B4:M4) -> 0 | O4: =+SUM($B4:$M4)-N4 -> 0
A5: Доп подразделение (назвать по-своему или пустое) | N5: =SUM(B5:M5) -> 0 | O5: =+SUM($B5:$M5)-N5 -> 0
A6: Количество гостей/заказов: | B6: =+SUM(B7:B9) -> 0 | C6: =+SUM(C7:C9) -> 0 | D6: =+SUM(D7:D9) -> 3807 | E6: =+SUM(E7:E9) -> 8253 | F6: =+SUM(F7:F9) -> 9177 | G6: =+SUM(G7:G9) -> 9166 | H6: =+SUM(H7:H9) -> 0 | I6: =+SUM(I7:I9) -> 0 | ... N6: =+SUM(N7:N9) -> 30403 | O6: =+SUM($B6:$M6)-N6 -> 0
A7: зал | B7: 0 | D7: 3807 | E7: 8253 | F7: 9177 | G7: 9085 | N7: =SUM(B7:M7) -> 30322 | O7: =+SUM($B7:$M7)-N7 -> 0
A8: доставка | B8: 0 | G8: 81 | N8: =SUM(B8:M8) -> 81 | O8: =+SUM($B8:$M8)-N8 -> 0
A9: Доп подразделение (назвать по-своему или пустое) | N9: =SUM(B9:M9) -> 0 | O9: =+SUM($B9:$M9)-N9 -> 0
A10: Средний чек | B10: =IFERROR(B2*1000/B6,"") | C10: =IFERROR(C2*1000/C6,"") | D10: =IFERROR(D2*1000/D6,"") -> 1557.6307 | E10: =IFERROR(E2*1000/E6,"") -> 1661.6018 | F10: =IFERROR(F2*1000/F6,"") -> 1712.1706 | G10: =IFERROR(G2*1000/G6,"") -> 1555.0241 | H10: =IFERROR(H2*1000/H6,"") | I10: =IFERROR(I2*1000/I6,"") | ... N10: =IFERROR(N2*1000/N6,"") -> 1631.7153
A11: зал | B11: =IFERROR(B3*1000/B7,"-") -> - | C11: =IFERROR(C3*1000/C7,"-") -> - | D11: =IFERROR(D3*1000/D7,"-") -> 1557.6307 | E11: =IFERROR(E3*1000/E7,"-") -> 1661.6018 | F11: =IFERROR(F3*1000/F7,"-") -> 1712.1706 | G11: =IFERROR(G3*1000/G7,"-") -> 1568.8884 | H11: =IFERROR(H3*1000/H7,"-") -> - | I11: =IFERROR(I3*1000/I7,"-") -> - | ... N11: =IFERROR(N3*1000/N7,"-") -> 1636.0742
A12: доставка | B12: =IFERROR(B4*1000/B8,"-") -> - | C12: =IFERROR(C4*1000/C8,"-") -> - | D12: =IFERROR(D4*1000/D8,"-") -> - | E12: =IFERROR(E4*1000/E8,"-") -> - | F12: =IFERROR(F4*1000/F8,"-") -> - | G12: =IFERROR(G4*1000/G8,"-") -> 0 | H12: =IFERROR(H4*1000/H8,"-") -> - | I12: =IFERROR(I4*1000/I8,"-") -> - | ... N12: =IFERROR(N4*1000/N8,"-") -> 0
A13: Доп подразделение (назвать по-своему или пустое) | B13: =IFERROR(B5*1000/B9,"-") -> - | C13: =IFERROR(C5*1000/C9,"-") -> - | D13: =IFERROR(D5*1000/D9,"-") -> - | E13: =IFERROR(E5*1000/E9,"-") -> - | F13: =IFERROR(F5*1000/F9,"-") -> - | G13: =IFERROR(G5*1000/G9,"-") -> - | H13: =IFERROR(H5*1000/H9,"-") -> - | I13: =IFERROR(I5*1000/I9,"-") -> - | ... N13: =IFERROR(N5*1000/N9,"-") -> -
A14: Себестоимость ИТОГО | B14: =+B15+B19 -> 0 | C14: =+C15+C19 -> 0 | D14: =+D15+D19 -> 2056.6998 | E14: =+E15+E19 -> 3982.4001 | F14: =+F15+F19 -> 4620.2513 | G14: =+G15+G19 -> 4111.6563 | H14: =+H15+H19 -> 0 | I14: =+I15+I19 -> 0 | ... N14: =+N15+N19 -> 14771.008 | O14: =+SUM($B14:$M14)-N14 -> 0
A15: Себестоимость реализации, всего, в т.ч. | B15: =+SUM(B16:B18) -> 0 | C15: =+SUM(C16:C18) -> 0 | D15: =+SUM(D16:D18) -> 1600.561 | E15: =+SUM(E16:E18) -> 3746.317 | F15: =+SUM(F16:F18) -> 4343.27 | G15: =+SUM(G16:G18) -> 3960.784 | H15: =+SUM(H16:H18) -> 0 | I15: =+SUM(I16:I18) -> 0 | ... N15: =+SUM(N16:N18) -> 13650.932 | O15: =+SUM($B15:$M15)-N15 -> 0
A16: зал | B16: 0 | D16: =2056.7-456.139 -> 1600.561 | E16: =3982.4-236.083 -> 3746.317 | F16: 4343.27 | G16: 3960.784 | N16: =SUM(B16:M16) -> 13650.932 | O16: =+SUM($B16:$M16)-N16 -> 0
A17: доставка | B17: 0 | N17: =SUM(B17:M17) -> 0 | O17: =+SUM($B17:$M17)-N17 -> 0
A18: Доп подразделение (назвать по-своему или пустое) | B18: 0 | N18: =SUM(B18:M18) -> 0 | O18: =+SUM($B18:$M18)-N18 -> 0
A19: Производственные показатели | B19: =+Расходы!B269/1000 -> 0 | C19: =+Расходы!C269/1000 -> 0 | D19: =+Расходы!D269/1000 -> 456.13882 | E19: =+Расходы!E269/1000 -> 236.08315 | F19: =+Расходы!F269/1000 -> 276.98128 | G19: =+Расходы!G269/1000 -> 150.87233 | H19: =+Расходы!H269/1000 -> 0 | I19: =+Расходы!I269/1000 -> 0 | ... M19: =+Расходы!M269/1000 -> 0 | N19: =SUM(B19:M19) -> 1120.0756 | O19: =+SUM($B19:$M19)-N19 -> 0
A20: Валовая прибыль | B20: =SUM(B21:B23) -> 0 | C20: =SUM(C21:C23) -> 0 | D20: =SUM(D21:D23) -> 3873.2002 | E20: =SUM(E21:E23) -> 9730.7999 | F20: =SUM(F21:F23) -> 11092.339 | G20: =SUM(G21:G23) -> 10141.695 | H20: =SUM(H21:H23) -> 0 | I20: =SUM(I21:I23) -> 0 | ... N20: =SUM(N21:N23) -> 34838.033 | O20: =+SUM($B20:$M20)-N20 -> 0
A21: зал | B21: =SUM(B3-B16-B19) -> 0 | C21: =SUM(C3-C16-C19) -> 0 | D21: =SUM(D3-D16-D19) -> 3873.2002 | E21: =SUM(E3-E16-E19) -> 9730.7999 | F21: =SUM(F3-F16-F19) -> 11092.339 | G21: =SUM(G3-G16-G19) -> 10141.695 | H21: =SUM(H3-H16-H19) -> 0 | I21: =SUM(I3-I16-I19) -> 0 | ... N21: =SUM(N3-N16-N19) -> 34838.033 | O21: =+SUM($B21:$M21)-N21 -> 0
A22: доставка | B22: =SUM(B4-B17) -> 0 | C22: =SUM(C4-C17) -> 0 | D22: =SUM(D4-D17) -> 0 | E22: =SUM(E4-E17) -> 0 | F22: =SUM(F4-F17) -> 0 | G22: =SUM(G4-G17) -> 0 | H22: =SUM(H4-H17) -> 0 | I22: =SUM(I4-I17) -> 0 | ... N22: =SUM(N4-N17) -> 0 | O22: =+SUM($B22:$M22)-N22 -> 0
A23: Доп подразделение (назвать по-своему или пустое) | B23: =SUM(B5-B18) -> 0 | C23: =SUM(C5-C18) -> 0 | D23: =SUM(D5-D18) -> 0 | E23: =SUM(E5-E18) -> 0 | F23: =SUM(F5-F18) -> 0 | G23: =SUM(G5-G18) -> 0 | H23: =SUM(H5-H18) -> 0 | I23: =SUM(I5-I18) -> 0 | ... N23: =SUM(N5-N18) -> 0 | O23: =+SUM($B23:$M23)-N23 -> 0
A24: % наценки | B24: =IFERROR((B2/B15-1)*100,"-") -> - | C24: =IFERROR((C2/C15-1)*100,"-") -> - | D24: =IFERROR((D2/D15-1)*100,"-") -> 270.48885 | E24: =IFERROR((E2/E15-1)*100,"-") -> 266.04484 | F24: =IFERROR((F2/F15-1)*100,"-") -> 261.76867 | G24: =IFERROR((G2/G15-1)*100,"-") -> 259.86186 | H24: =IFERROR((H2/H15-1)*100,"-") -> - | I24: =IFERROR((I2/I15-1)*100,"-") -> - | ... N24: =IFERROR((N2/N15-1)*100,"-") -> 263.41138
A25: зал | B25: =IFERROR((B3/B16-1)*100,"-") -> - | C25: =IFERROR((C3/C16-1)*100,"-") -> - | D25: =IFERROR((D3/D16-1)*100,"-") -> 270.48885 | E25: =IFERROR((E3/E16-1)*100,"-") -> 266.04484 | F25: =IFERROR((F3/F16-1)*100,"-") -> 261.76867 | G25: =IFERROR((G3/G16-1)*100,"-") -> 259.86186 | H25: =IFERROR((H3/H16-1)*100,"-") -> - | I25: =IFERROR((I3/I16-1)*100,"-") -> - | ... N25: =IFERROR((N3/N16-1)*100,"-") -> 263.41138
A26: доставка | B26: =IFERROR((B4/B17-1)*100,"-") -> - | C26: =IFERROR((C4/C17-1)*100,"-") -> - | D26: =IFERROR((D4/D17-1)*100,"-") -> - | E26: =IFERROR((E4/E17-1)*100,"-") -> - | F26: =IFERROR((F4/F17-1)*100,"-") -> - | G26: =IFERROR((G4/G17-1)*100,"-") -> - | H26: =IFERROR((H4/H17-1)*100,"-") -> - | I26: =IFERROR((I4/I17-1)*100,"-") -> - | ... N26: =IFERROR((N4/N17-1)*100,"-") -> -
A27: Доп подразделение (назвать по-своему или пустое) | B27: =IFERROR((B5/B18-1)*100,"-") -> - | C27: =IFERROR((C5/C18-1)*100,"-") -> - | D27: =IFERROR((D5/D18-1)*100,"-") -> - | E27: =IFERROR((E5/E18-1)*100,"-") -> - | F27: =IFERROR((F5/F18-1)*100,"-") -> - | G27: =IFERROR((G5/G18-1)*100,"-") -> - | H27: =IFERROR((H5/H18-1)*100,"-") -> - | I27: =IFERROR((I5/I18-1)*100,"-") -> - | ... N27: =IFERROR((N5/N18-1)*100,"-") -> -
A28: Операционные расходы | B28: =SUM(B29:B31) -> 0 | C28: =SUM(C29:C31) -> 0 | D28: =SUM(D29:D31) -> 2581.3719 | E28: =SUM(E29:E31) -> 7143.4247 | F28: =SUM(F29:F31) -> 8278.0935 | G28: =SUM(G29:G31) -> 7690.9786 | H28: =SUM(H29:H31) -> 0 | I28: =SUM(I29:I31) -> 0 | ... N28: =SUM(N29:N31) -> 25693.869 | O28: =+SUM($B28:$M28)-N28 -> 0
A29: текущие расходы заведения | B29: =+Расходы!B178/1000 -> 0 | C29: =Расходы!C178/1000 -> 0 | D29: =Расходы!D178/1000 -> 2581.3719 | E29: =Расходы!E178/1000 -> 7143.4247 | F29: =Расходы!F178/1000 -> 8247.9887 | G29: =Расходы!G178/1000 -> 7678.8271 | H29: =Расходы!H178/1000 -> 0 | I29: =Расходы!I178/1000 -> 0 | J29: =Расходы!J178/1000 -> 0 | ... M29: =Расходы!M178/1000 -> 0 | N29: =SUM(B29:M29) -> 25651.612 | O29: =+SUM($B29:$M29)-N29 -> 0
A30: расходы доставки | B30: =+Расходы!B208/1000 -> 0 | C30: =Расходы!C208/1000 -> 0 | D30: =Расходы!D208/1000 -> 0 | E30: =Расходы!E208/1000 -> 0 | F30: =Расходы!F208/1000 -> 30.10478 | G30: =Расходы!G208/1000 -> 12.15149 | H30: =Расходы!H208/1000 -> 0 | I30: =Расходы!I208/1000 -> 0 | J30: =Расходы!J208/1000 -> 0 | ... M30: =Расходы!M208/1000 -> 0 | N30: =SUM(B30:M30) -> 42.25627 | O30: =+SUM($B30:$M30)-N30 -> 0
A31: текущие расходы "Доп.подразделение" | B31: =+'расходы Доп.подразделение'!B178/1000 -> 0 | C31: ='расходы Доп.подразделение'!C178 -> 0 | D31: ='расходы Доп.подразделение'!D178 -> 0 | E31: ='расходы Доп.подразделение'!E178 -> 0 | F31: ='расходы Доп.подразделение'!F178 -> 0 | G31: ='расходы Доп.подразделение'!G178 -> 0 | H31: ='расходы Доп.подразделение'!H178 -> 0 | I31: ='расходы Доп.подразделение'!I178 -> 0 | J31: ='расходы Доп.подразделение'!J178 -> 0 | ... M31: ='расходы Доп.подразделение'!M178 -> 0 | N31: =SUM(B31:M31) -> 0 | O31: =+SUM($B31:$M31)-N31 -> 0
A32: Операционная прибыль | B32: =B33+B34 -> 0 | C32: =+SUM(C33:C35) -> 0 | D32: =+SUM(D33:D35) -> 1291.8283 | E32: =+SUM(E33:E35) -> 2587.3752 | F32: =+SUM(F33:F35) -> 2814.2452 | G32: =+SUM(G33:G35) -> 2450.716 | H32: =+SUM(H33:H35) -> 0 | I32: =+SUM(I33:I35) -> 0 | J32: =+SUM(J33:J35) -> 0 | ... N32: =+SUM(N33:N35) -> 9144.1647 | O32: =+SUM($B32:$M32)-N32 -> 0
A33: по основной деятельности | B33: =+B21-B29 -> 0 | C33: =+C21-C29 -> 0 | D33: =+D21-D29 -> 1291.8283 | E33: =+E21-E29 -> 2587.3752 | F33: =+F21-F29 -> 2844.35 | G33: =+G21-G29 -> 2462.8675 | H33: =+H21-H29 -> 0 | I33: =+I21-I29 -> 0 | ... N33: =+N21-N29 -> 9186.4209 | O33: =+SUM($B33:$M33)-N33 -> 0
A34: доставка | B34: =+B22-B30 -> 0 | C34: =+C22-C30 -> 0 | D34: =+D22-D30 -> 0 | E34: =+E22-E30 -> 0 | F34: =+F22-F30 -> -30.10478 | G34: =+G22-G30 -> -12.15149 | H34: =+H22-H30 -> 0 | I34: =+I22-I30 -> 0 | ... N34: =+N22-N30 -> -42.25627 | O34: =+SUM($B34:$M34)-N34 -> 0
A35: Доп.подразделение | B35: =+B23-B31 -> 0 | C35: =+C23-C31 -> 0 | D35: =+D23-D31 -> 0 | E35: =+E23-E31 -> 0 | F35: =+F23-F31 -> 0 | G35: =+G23-G31 -> 0 | H35: =+H23-H31 -> 0 | I35: =+I23-I31 -> 0 | ... N35: =+N23-N31 -> 0 | O35: =+SUM($B35:$M35)-N35 -> 0
O36: =+SUM($B36:$M36)-N36 -> 0
A37: Неоперационные доходы | N37: =SUM(B37:M37) -> 0 | O37: =+SUM($B37:$M37)-N37 -> 0
A39: Неоперационные расходы | B39: =SUM(B40:B51) -> 0 | C39: =SUM(C40:C51) -> 0 | D39: =SUM(D40:D51) -> 95.47676 | E39: =SUM(E40:E51) -> 792.7881 | F39: =SUM(F40:F51) -> 741.42911 | G39: =SUM(G40:G51) -> 799.28149 | H39: =SUM(H40:H51) -> 0 | I39: =SUM(I40:I51) -> 0 | ... N39: =SUM(N40:N51) -> 2428.9755 | O39: =+SUM($B39:$M39)-N39 -> 0
A40: Расходы служб | B40: =Расходы!B211/1000 -> 0 | C40: =Расходы!C211/1000 -> 0 | D40: =Расходы!D211/1000 -> 0 | E40: =Расходы!E211/1000 -> 404.92417 | F40: =Расходы!F211/1000 -> 382.80317 | G40: =Расходы!G211/1000 -> 300.3714 | H40: =Расходы!H211/1000 -> 0 | I40: =Расходы!I211/1000 -> 0 | ... M40: =Расходы!M211/1000 -> 0 | N40: =SUM(B40:M40) -> 1088.0987 | O40: =+SUM($B40:$M40)-N40 -> 0
A41: Налоги | B41: =+Расходы!B224/1000 -> 0 | C41: =+Расходы!C224/1000 -> 0 | D41: =+Расходы!D224/1000 -> 95.47676 | E41: =+Расходы!E224/1000 -> 342.82981 | F41: =+Расходы!F224/1000 -> 316.9573 | G41: =+Расходы!G224/1000 -> 362.167 | H41: =+Расходы!H224/1000 -> 0 | I41: =+Расходы!I224/1000 -> 0 | ... M41: =+Расходы!M224/1000 -> 0 | N41: =SUM(B41:M41) -> 1117.4309 | O41: =+SUM($B41:$M41)-N41 -> 0
...

Sheet Расходы
A1: Статьи расходов | B1: январь | C1: февраль | D1: март | E1: апрель | F1: май | G1: июнь | H1: июль | I1: август | J1: сентябрь | K1: октябрь | L1: ноябрь | M1: декабрь | N1: Итого | O1: Проверка | P1: Код
A2: Расходы на персонал | B2: =+B3+B14+B18 -> 0 | C2: =+C3+C14+C18 -> 0 | D2: =+D3+D14+D18 -> 1595189 | E2: =+E3+E14+E18 -> 4034614.2 | F2: =+F3+F14+F18 -> 4515469.7 | G2: =+G3+G14+G18 -> 4392321.4 | H2: =+H3+H14+H18 -> 0 | I2: =+I3+I14+I18 -> 0 | ... N2: =+N3+N14+N18 -> 14537594 | O2: =+SUM($B2:$M2)-N2 -> 0 | P2: 00-000406 | S2: =H2/1000 -> 0
A3: Фонд оплаты труда | B3: =SUM(B4:B13) -> 0 | C3: =SUM(C4:C13) -> 0 | D3: =SUM(D4:D13) -> 1415086.2 | E3: =SUM(E4:E13) -> 3397840 | F3: =SUM(F4:F13) -> 3793805.5 | G3: =SUM(G4:G13) -> 3559808.4 | H3: =SUM(H4:H13) -> 0 | I3: =SUM(I4:I13) -> 0 | ... N3: =SUM(N4:N13) -> 12166540 | O3: =+SUM($B3:$M3)-N3 -> 0 | P3: 00-000174 | S3: =H3/1000 -> 0
A4: 01 ЗП Кухня | D4: 478220 | E4: 1469110 | F4: 1577040 | G4: 1453396 | N4: =SUM(B4:M4) -> 4977766 | O4: =+SUM($B4:$M4)-N4 -> 0 | P4: 00-000420 | S4: =H4/1000 -> 0
A5: 02 ЗП Зал | D5: 598690 | E5: 1112200.1 | F5: =1119464-18900 -> 1100564 | G5: 1107995.9 | N5: =SUM(B5:M5) -> 3919449.9 | O5: =+SUM($B5:$M5)-N5 -> 0 | P5: 00-000421 | S5: =H5/1000 -> 0
A6: 03 ЗП Клининг | D6: 167700 | E6: 447330 | F6: 466830 | G6: 469690 | N6: =SUM(B6:M6) -> 1551550 | O6: =+SUM($B6:$M6)-N6 -> 0 | P6: 00-000422 | S6: =H6/1000 -> 0
A7: 04 ЗП Прочие | D7: 170476.23 | E7: 369200 | F7: 563661.5 | G7: 520913 | N7: =SUM(B7:M7) -> 1624250.7 | O7: =+SUM($B7:$M7)-N7 -> 0 | P7: 00-000423 | S7: =H7/1000 -> 0
A8: Больничный | N8: =SUM(B8:M8) -> 0 | O8: =+SUM($B8:$M8)-N8 -> 0 | P8: 00-000221 | S8: =H8/1000 -> 0
A9: Доплаты индивидуальные | N9: =SUM(B9:M9) -> 0 | O9: =+SUM($B9:$M9)-N9 -> 0 | P9: 00-000259 | S9: =H9/1000 -> 0
A10: Материальная помощь | N10: =SUM(B10:M10) -> 0 | O10: =+SUM($B10:$M10)-N10 -> 0 | P10: 00-000270 | S10: =H10/1000 -> 0
A11: Отпускные | F11: 60000 | N11: =SUM(B11:M11) -> 60000 | O11: =+SUM($B11:$M11)-N11 -> 0 | P11: 00-000163 | S11: =H11/1000 -> 0
A12: Пособия | N12: =SUM(B12:M12) -> 0 | O12: =+SUM($B12:$M12)-N12 -> 0 | P12: 00-000250 | S12: =H12/1000 -> 0
A13: Премии | F13: 25710 | G13: 7813.53 | N13: =SUM(B13:M13) -> 33523.53 | O13: =+SUM($B13:$M13)-N13 -> 0 | P13: 00-000172 | S13: =H13/1000 -> 0
A14: Налоги ФОТ | B14: =SUM(B15:B17) -> 0 | C14: =SUM(C15:C17) -> 0 | D14: =SUM(D15:D17) -> 3180 | E14: =SUM(E15:E17) -> 179705.94 | F14: =SUM(F15:F17) -> 304912.9 | G14: =SUM(G15:G17) -> 375492.9 | H14: =SUM(H15:H17) -> 0 | I14: =SUM(I15:I17) -> 0 | ... N14: =SUM(N15:N17) -> 863291.74 | O14: =+SUM($B14:$M14)-N14 -> 0 | P14: 00-000424 | S14: =H14/1000 -> 0
A15: Взносы ФОТ | E15: 110870.94 | F15: 148335.9 | G15: 239893.9 | N15: =SUM(B15:M15) -> 499100.74 | O15: =+SUM($B15:$M15)-N15 -> 0 | P15: 00-000425 | S15: =H15/1000 -> 0
A16: НДФЛ ФОТ | E16: 65643 | F16: 153495 | G16: 135599 | N16: =SUM(B16:M16) -> 354737 | O16: =+SUM($B16:$M16)-N16 -> 0 | P16: 00-000069 | S16: =H16/1000 -> 0
A17: Самозанятые комиссия | D17: 3180 | E17: 3192 | F17: 3082 | N17: =SUM(B17:M17) -> 9454 | O17: =+SUM($B17:$M17)-N17 -> 0 | P17: 00-000005 | S17: =H17/1000 -> 0
A18: Затраты на персонал | B18: =SUM(B19:B28) -> 0 | C18: =SUM(C19:C28) -> 0 | D18: =SUM(D19:D28) -> 176922.75 | E18: =SUM(E19:E28) -> 457068.25 | F18: =SUM(F19:F28) -> 416751.32 | G18: =SUM(G19:G28) -> 457020.1 | H18: =SUM(H19:H28) -> 0 | I18: =SUM(I19:I28) -> 0 | ... N18: =SUM(N19:N28) -> 1507762.4 | O18: =+SUM($B18:$M18)-N18 -> 0 | P18: 00-000272 | S18: =H18/1000 -> 0
A19: Компенсация проезда | N19: =SUM(B19:M19) -> 0 | O19: =+SUM($B19:$M19)-N19 -> 0 | P19: 00-000343 | S19: =H19/1000 -> 0
A20: Медосмотр сотрудников | E20: 10500 | F20: 23000 | G20: 11700 | N20: =SUM(B20:M20) -> 45200 | O20: =+SUM($B20:$M20)-N20 -> 0 | P20: 00-000301 | S20: =H20/1000 -> 0
A21: Оплата проживания | N21: =SUM(B21:M21) -> 0 | O21: =+SUM($B21:$M21)-N21 -> 0 | P21: 00-000345 | S21: =H21/1000 -> 0
A22: Питание штата | D22: 67195.13 | E22: 91256.19 | F22: 94352.92 | G22: 108611.8 | N22: =SUM(B22:M22) -> 361416.04 | O22: =+SUM($B22:$M22)-N22 -> 0 | P22: 00-000061 | S22: =H22/1000 -> 0
A23: Подарки сотрудникам | D23: 37455.62 | E23: 2362.01 | F23: 5000 | N23: =SUM(B23:M23) -> 44817.63 | O23: =+SUM($B23:$M23)-N23 -> 0 | P23: 00-000025 | S23: =H23/1000 -> 0
A24: Содержание столовой | N24: =SUM(B24:M24) -> 0 | O24: =+SUM($B24:$M24)-N24 -> 0 | P24: 00-000303 | S24: =H24/1000 -> 0
A25: Сотовая связь | N25: =SUM(B25:M25) -> 0 | O25: =+SUM($B25:$M25)-N25 -> 0 | P25: 00-000095 | S25: =H25/1000 -> 0
A26: Спецодежда | D26: 5129 | E26: 49748 | F26: 19992 | G26: 5256 | N26: =SUM(B26:M26) -> 80125 | O26: =+SUM($B26:$M26)-N26 -> 0 | P26: 00-000094 | S26: =H26/1000 -> 0
A27: Такси | D27: 67143 | E27: 303202.05 | F27: 274406.4 | G27: 331452.3 | N27: =SUM(B27:M27) -> 976203.75 | O27: =+SUM($B27:$M27)-N27 -> 0 | P27: 00-000080 | S27: =H27/1000 -> 0
A28: Такси завтраки | N28: =SUM(B28:M28) -> 0 | O28: =+SUM($B28:$M28)-N28 -> 0 | P28: 00-000276 | S28: =H28/1000 -> 0
A30: Арендные платежи | B30: =SUM(B32:B42) -> 0 | C30: =SUM(C32:C42) -> 0 | D30: =SUBTOTAL(9,D31:D39) -> 195161.29 | E30: =SUBTOTAL(9,E31:E39) -> 576880.1 | F30: =SUBTOTAL(9,F31:F39) -> 561000 | G30: =SUM(G32:G42) -> 564348 | H30: =SUM(H32:H42) -> 0 | I30: =SUM(I32:I42) -> 0 | J30: =SUM(J32:J42) -> 0 | K30: =SUM(K32:K42) -> 0 | L30: =SUM(L32:L42) -> 0 | M30: =SUM(M32:M42) -> 0 | N30: =SUM(N32:N42) -> 1891389.4 | O30: =+SUM($B30:$M30)-N30 -> 6000 | P30: 00-000181 | S30: =H30/1000 -> 0
A31: Аренда алкогольного склада | F31: 6000 | N31: =SUM(B31:M31) -> 6000 | O31: =+SUM($B31:$M31)-N31 -> 0 | P31: 00-000187 | S31: =H31/1000 -> 0
A32: Аренда гаража | N32: =SUM(B32:M32) -> 0 | O32: =+SUM($B32:$M32)-N32 -> 0 | P32: 00-000298 | S32: =H32/1000 -> 0
A33: Аренда заведения | D33: 195161.29 | E33: 550000 | F33: 550000 | G33: 550000 | N33: =SUM(B33:M33) -> 1845161.3 | O33: =+SUM($B33:$M33)-N33 -> 0 | P33: 00-000026 | S33: =H33/1000 -> 0
A34: Аренда земельного участка | N34: =SUM(B34:M34) -> 0 | O34: =+SUM($B34:$M34)-N34 -> 0 | P34: 00-000348 | S34: =H34/1000 -> 0
A35: Аренда имущества | N35: =SUM(B35:M35) -> 0 | O35: =+SUM($B35:$M35)-N35 -> 0 | P35: 00-000312 | S35: =H35/1000 -> 0
A36: Аренда офисов | N36: =SUM(B36:M36) -> 0 | O36: =+SUM($B36:$M36)-N36 -> 0 | P36: 00-000182 | S36: =H36/1000 -> 0
A37: Аренда парковочных мест | N37: =SUM(B37:M37) -> 0 | O37: =+SUM($B37:$M37)-N37 -> 0 | P37: 00-000332 | S37: =H37/1000 -> 0
A38: Аренда помещения мусорокамеры (Капитанская 12) | N38: =SUM(B38:M38) -> 0 | O38: =+SUM($B38:$M38)-N38 -> 0 | P38: 00-000193 | S38: =H38/1000 -> 0
A39: Аренда склада | E39: 26880.1 | F39: 5000 | G39: 10000 | N39: =SUM(B39:M39) -> 41880.1 | O39: =+SUM($B39:$M39)-N39 -> 0 | P39: 00-000204 | S39: =H39/1000 -> 0
A40: Аренда склада Гладкова | G40: 4348 | N40: =SUM(B40:M40) -> 4348 | O40: =+SUM($B40:$M40)-N40 -> 0 | P40: 00-000215 | S40: =H40/1000 -> 0
A41: Аренда цеха | N41: =SUM(B41:M41) -> 0 | O41: =+SUM($B41:$M41)-N41 -> 0 | P41: 00-000203 | S41: =H41/1000 -> 0
...

Sheet расходы Доп.подразделение
A1: Статьи расходов | B1: январь | C1: февраль | D1: март | E1: апрель | F1: май | G1: июнь | H1: июль | I1: август | J1: сентябрь | K1: октябрь | L1: ноябрь | M1: декабрь | N1: Итого | O1: Проверка | P1: Код
A2: Расходы на персонал | B2: =+B3+B14+B18 -> 0 | C2: =+C3+C14+C18 -> 0 | D2: =+D3+D14+D18 -> 0 | E2: =+E3+E14+E18 -> 0 | F2: =+F3+F14+F18 -> 0 | G2: =+G3+G14+G18 -> 0 | H2: =+H3+H14+H18 -> 0 | I2: =+I3+I14+I18 -> 0 | ... N2: =+N3+N14+N18 -> 0 | O2: =+SUM($B2:$M2)-N2 -> 0 | P2: 00-000406 | S2: =H2/1000 -> 0
A3: Фонд оплаты труда | B3: =SUM(B4:B13) -> 0 | C3: =SUM(C4:C13) -> 0 | D3: =SUM(D4:D13) -> 0 | E3: =SUM(E4:E13) -> 0 | F3: =SUM(F4:F13) -> 0 | G3: =SUM(G4:G13) -> 0 | H3: =SUM(H4:H13) -> 0 | I3: =SUM(I4:I13) -> 0 | ... N3: =SUM(N4:N13) -> 0 | O3: =+SUM($B3:$M3)-N3 -> 0 | P3: 00-000174 | S3: =H3/1000 -> 0
A4: 01 ЗП Кухня | N4: =SUM(B4:M4) -> 0 | O4: =+SUM($B4:$M4)-N4 -> 0 | P4: 00-000420 | S4: =H4/1000 -> 0
A5: 02 ЗП Зал | N5: =SUM(B5:M5) -> 0 | O5: =+SUM($B5:$M5)-N5 -> 0 | P5: 00-000421 | S5: =H5/1000 -> 0
A6: 03 ЗП Клининг | N6: =SUM(B6:M6) -> 0 | O6: =+SUM($B6:$M6)-N6 -> 0 | P6: 00-000422 | S6: =H6/1000 -> 0
A7: 04 ЗП Прочие | N7: =SUM(B7:M7) -> 0 | O7: =+SUM($B7:$M7)-N7 -> 0 | P7: 00-000423 | S7: =H7/1000 -> 0
A8: Больничный | N8: =SUM(B8:M8) -> 0 | O8: =+SUM($B8:$M8)-N8 -> 0 | P8: 00-000221 | S8: =H8/1000 -> 0
A9: Доплаты индивидуальные | N9: =SUM(B9:M9) -> 0 | O9: =+SUM($B9:$M9)-N9 -> 0 | P9: 00-000259 | S9: =H9/1000 -> 0
A10: Материальная помощь | N10: =SUM(B10:M10) -> 0 | O10: =+SUM($B10:$M10)-N10 -> 0 | P10: 00-000270 | S10: =H10/1000 -> 0
A11: Отпускные | N11: =SUM(B11:M11) -> 0 | O11: =+SUM($B11:$M11)-N11 -> 0 | P11: 00-000163 | S11: =H11/1000 -> 0
A12: Пособия | N12: =SUM(B12:M12) -> 0 | O12: =+SUM($B12:$M12)-N12 -> 0 | P12: 00-000250 | S12: =H12/1000 -> 0
A13: Премии | N13: =SUM(B13:M13) -> 0 | O13: =+SUM($B13:$M13)-N13 -> 0 | P13: 00-000172 | S13: =H13/1000 -> 0
A14: Налоги ФОТ | B14: =SUM(B15:B17) -> 0 | C14: =SUM(C15:C17) -> 0 | D14: =SUM(D15:D17) -> 0 | E14: =SUM(E15:E17) -> 0 | F14: =SUM(F15:F17) -> 0 | G14: =SUM(G15:G17) -> 0 | H14: =SUM(H15:H17) -> 0 | I14: =SUM(I15:I17) -> 0 | ... N14: =SUM(N15:N17) -> 0 | O14: =+SUM($B14:$M14)-N14 -> 0 | P14: 00-000424 | S14: =H14/1000 -> 0
A15: Взносы ФОТ | N15: =SUM(B15:M15) -> 0 | O15: =+SUM($B15:$M15)-N15 -> 0 | P15: 00-000425 | S15: =H15/1000 -> 0
A16: НДФЛ ФОТ | N16: =SUM(B16:M16) -> 0 | O16: =+SUM($B16:$M16)-N16 -> 0 | P16: 00-000069 | S16: =H16/1000 -> 0
A17: Самозанятые комиссия | N17: =SUM(B17:M17) -> 0 | O17: =+SUM($B17:$M17)-N17 -> 0 | P17: 00-000005 | S17: =H17/1000 -> 0
A18: Затраты на персонал | B18: =SUM(B19:B26) -> 0 | C18: =SUM(C19:C26) -> 0 | D18: =SUM(D19:D26) -> 0 | E18: =SUM(E19:E26) -> 0 | F18: =SUM(F19:F26) -> 0 | G18: =SUM(G19:G26) -> 0 | H18: =SUM(H19:H26) -> 0 | I18: =SUM(I19:I26) -> 0 | ... N18: =SUM(N19:N26) -> 0 | O18: =+SUM($B18:$M18)-N18 -> 0 | P18: 00-000272 | S18: =H18/1000 -> 0
A19: Компенсация проезда | N19: =SUM(B19:M19) -> 0 | O19: =+SUM($B19:$M19)-N19 -> 0 | P19: 00-000343 | S19: =H19/1000 -> 0
A20: Медосмотр сотрудников | N20: =SUM(B20:M20) -> 0 | O20: =+SUM($B20:$M20)-N20 -> 0 | P20: 00-000301 | S20: =H20/1000 -> 0
A21: Оплата проживания | N21: =SUM(B21:M21) -> 0 | O21: =+SUM($B21:$M21)-N21 -> 0 | P21: 00-000345 | S21: =H21/1000 -> 0
A22: Питание штата | N22: =SUM(B22:M22) -> 0 | O22: =+SUM($B22:$M22)-N22 -> 0 | P22: 00-000061 | S22: =H22/1000 -> 0
A23: Подарки сотрудникам | N23: =SUM(B23:M23) -> 0 | O23: =+SUM($B23:$M23)-N23 -> 0 | P23: 00-000025 | S23: =H23/1000 -> 0
A24: Содержание столовой | N24: =SUM(B24:M24) -> 0 | O24: =+SUM($B24:$M24)-N24 -> 0 | P24: 00-000303 | S24: =H24/1000 -> 0
A25: Сотовая связь | N25: =SUM(B25:M25) -> 0 | O25: =+SUM($B25:$M25)-N25 -> 0 | P25: 00-000095 | S25: =H25/1000 -> 0
A26: Спецодежда | N26: =SUM(B26:M26) -> 0 | O26: =+SUM($B26:$M26)-N26 -> 0 | P26: 00-000094 | S26: =H26/1000 -> 0
A28: Арендные платежи | B28: =SUM(B30:B40) -> 0 | C28: =SUM(C30:C40) -> 0 | D28: =SUM(D30:D40) -> 0 | E28: =SUM(E30:E40) -> 0 | F28: =SUM(F30:F40) -> 0 | G28: =SUM(G30:G40) -> 0 | H28: =SUM(H30:H40) -> 0 | I28: =SUM(I30:I40) -> 0 | ... N28: =SUM(N30:N40) -> 0 | O28: =+SUM($B28:$M28)-N28 -> 0 | P28: 00-000181 | S28: =H28/1000 -> 0
A29: Аренда алкогольного склада | N29: =SUM(B29:M29) -> 0 | O29: =+SUM($B29:$M29)-N29 -> 0 | P29: 00-000187 | S29: =H29/1000 -> 0
A30: Аренда гаража | N30: =SUM(B30:M30) -> 0 | O30: =+SUM($B30:$M30)-N30 -> 0 | P30: 00-000298 | S30: =H30/1000 -> 0
A31: Аренда заведения | N31: =SUM(B31:M31) -> 0 | O31: =+SUM($B31:$M31)-N31 -> 0 | P31: 00-000026 | S31: =H31/1000 -> 0
A32: Аренда земельного участка | N32: =SUM(B32:M32) -> 0 | O32: =+SUM($B32:$M32)-N32 -> 0 | P32: 00-000348 | S32: =H32/1000 -> 0
A33: Аренда имущества | N33: =SUM(B33:M33) -> 0 | O33: =+SUM($B33:$M33)-N33 -> 0 | P33: 00-000312 | S33: =H33/1000 -> 0
A34: Аренда офисов | N34: =SUM(B34:M34) -> 0 | O34: =+SUM($B34:$M34)-N34 -> 0 | P34: 00-000182 | S34: =H34/1000 -> 0
A35: Аренда парковочных мест | N35: =SUM(B35:M35) -> 0 | O35: =+SUM($B35:$M35)-N35 -> 0 | P35: 00-000332 | S35: =H35/1000 -> 0
A36: Аренда помещения мусорокамеры (Капитанская 12) | N36: =SUM(B36:M36) -> 0 | O36: =+SUM($B36:$M36)-N36 -> 0 | P36: 00-000193 | S36: =H36/1000 -> 0
A37: Аренда склада | N37: =SUM(B37:M37) -> 0 | O37: =+SUM($B37:$M37)-N37 -> 0 | P37: 00-000204 | S37: =H37/1000 -> 0
A38: Аренда склада Гладкова | N38: =SUM(B38:M38) -> 0 | O38: =+SUM($B38:$M38)-N38 -> 0 | P38: 00-000215 | S38: =H38/1000 -> 0
A39: Аренда цеха | N39: =SUM(B39:M39) -> 0 | O39: =+SUM($B39:$M39)-N39 -> 0 | P39: 00-000203 | S39: =H39/1000 -> 0
A40: Услуги автопарковки | N40: =SUM(B40:M40) -> 0 | O40: =+SUM($B40:$M40)-N40 -> 0 | P40: 00-000341 | S40: =H40/1000 -> 0
A41: Коммунальные расходы | B41: =SUM(B42:B50) -> 0 | C41: =SUM(C42:C50) -> 0 | D41: =SUM(D42:D50) -> 0 | E41: =SUM(E42:E50) -> 0 | F41: =SUM(F42:F50) -> 0 | G41: =SUM(G42:G50) -> 0 | H41: =SUM(H42:H50) -> 0 | I41: =SUM(I42:I50) -> 0 | ... N41: =SUM(N42:N50) -> 0 | O41: =+SUM($B41:$M41)-N41 -> 0 | P41: 00-000180 | S41: =H41/1000 -> 0
...

Sheet баланс
B1: 46022 | C1: 46053 | D1: 46081 | E1: 46112 | F1: 46142 | G1: 46173 | H1: 46203 | I1: 46234 | J1: 46265 | K1: 46295 | L1: 46326 | M1: 46356 | N1: 46387 | Q1: =+G1 -> 46173
A2: Актив | Q2: =-(G9-G20)/1000 -> -828.67886
A3: Текущие активы
A4: руб. | E4: 50072.57 | F4: 166003.53 | G4: 174229.79 | H4: 643865.9
A5: Б/нал | D5: 11688.95 | E5: 2944817.9 | F5: 393968.96 | G5: 1539376.4 | H5: 579478.31
A6: Подотчеты | D6: 405812 | E6: 209552.61 | F6: 174126.4 | G6: 48924.81 | H6: 62537.58
A7: Покупатели | E7: -70000 | F7: -96620 | G7: -45638.4 | H7: -19100.08
A8: Бонусный счет | E8: -3000 | F8: =27333.99-17446.47 -> 9887.52 | G8: =29259.99 -> 29259.99 | H8: 922511.1
A9: Запасы (товары на складе) | D9: 474058.45 | E9: 2318952.8 | F9: 3001149 | G9: 2722690.5 | H9: 2687852.2
A10: Итого по разделу №1 | B10: =SUM(B4:B9) -> 0 | C10: =SUM(C4:C9) -> 0 | D10: =SUM(D4:D9) -> 891559.4 | E10: =SUM(E4:E9) -> 5450395.9 | F10: =SUM(F4:F9) -> 3648515.4 | G10: =SUM(G4:G9) -> 4468843.1 | H10: =SUM(H4:H9) -> 4877145 | I10: =SUM(I4:I9) -> 0 | ... N10: =SUM(N4:N9) -> 0
A11: Внеоборотные активы
A12: Инвестиционные расходы | D12: 45981733 | E12: 53336355 | F12: 55126452 | G12: 56899699 | H12: 57501542
A13: Имущество | D13: 22609582 | E13: 26301554 | F13: 26841221 | G13: 31848980 | H13: 32538728
A14: Итого по разделу №2 | B14: =SUM(B12:B13) -> 0 | C14: =SUM(C12:C13) -> 0 | D14: =SUM(D12:D13) -> 68591315 | E14: =SUM(E12:E13) -> 79637909 | F14: =SUM(F12:F13) -> 81967673 | G14: =SUM(G12:G13) -> 88748680 | H14: =SUM(H12:H13) -> 90040270 | I14: =SUM(I12:I13) -> 0 | ... N14: =SUM(N12:N13) -> 0
A15: Баланс | B15: =B14+B10 -> 0 | C15: =C14+C10 -> 0 | D15: =D14+D10 -> 69482874 | E15: =E14+E10 -> 85088305 | F15: =F14+F10 -> 85616189 | G15: =G14+G10 -> 93217523 | H15: =H14+H10 -> 94917415 | I15: =I14+I10 -> 0 | ... N15: =N14+N10 -> 0
A16: Пассив
A17: Привлеченный капитал
A18: Кредиторы БГ (67сч) | D18: 5017381.1 | E18: 6355983.9 | F18: 5216340.7 | G18: 6298090.8 | H18: 6436219.2
A19: Займы персоналу (73сч)
A20: Поставщик продуктов | E20: =-1757749*2+1948891.68 -> -1566606.3 | F20: 1855387 | G20: 1894011.7 | H20: 1806923.7
A21: Расчеты с поставщиками хозтоваров и услуг | D21: -6191978.3 | E21: -191142.68 | F21: -4269661 | G21: -51312.6 | H21: 84531.66
A22: Расчеты с бюджетом | D22: -49262.93 | E22: 6913.83 | F22: 77156.88 | G22: 219836.18 | H22: 360894.18
A23: Зарплата персонала | D23: 654421.79 | E23: 1830983 | F23: 2116146 | G23: 2163261.9 | H23: 1883777.5
A24: Прочие дебиторы, кредиторы | E24: -58618
A25: Займы внутренние
A26: Расчеты по кредитам и займам
A27: Расчеты с учред.(взносы в УК) | D27: 70052312 | E27: 77514493 | F27: 77629613 | G27: 77629613 | H27: 77629613
A28: Итого по разделу №1 | B28: =SUM(B18:B27) -> 0 | C28: =SUM(C18:C27) -> 0 | D28: =SUM(D18:D27) -> 69482874 | E28: =SUM(E18:E27) -> 83892007 | F28: =SUM(F18:F27) -> 82624983 | G28: =SUM(G18:G27) -> 88153501 | H28: =SUM(H18:H27) -> 88201960 | I28: =SUM(I18:I27) -> 0 | ... N28: =SUM(N18:N27) -> 0
A29: Собственный капитал
A30: Фонды собственных средств | B30: =B15-B28 -> 0 | C30: =C15-C28 -> 0 | D30: =D15-D28 -> 0 | E30: =E15-E28 -> 1196298.1 | F30: =F15-F28 -> 2991205.6 | G30: =G15-G28 -> 5064021.7 | H30: =H15-H28 -> 6715455.4 | I30: =I15-I28 -> 0 | ... N30: =N15-N28 -> 0
A31: Изменение собственных средств | C31: =B30 -> 0 | D31: =C30 -> 0 | E31: =D30 -> 0 | F31: =E30 -> 1196298.1 | G31: =F30 -> 2991205.6 | H31: =G30 -> 5064021.7 | I31: =H30 -> 6715455.4 | J31: =I30 -> 0 | ... N31: =M30 -> 0
A32: Итого по разделу №2 | B32: =SUM(B30) -> 0 | C32: =SUM(C30) -> 0 | D32: =SUM(D30) -> 0 | E32: =SUM(E30) -> 1196298.1 | F32: =SUM(F30) -> 2991205.6 | G32: =SUM(G30) -> 5064021.7 | H32: =SUM(H30) -> 6715455.4 | I32: =SUM(I30) -> 0 | ... N32: =SUM(N30) -> 0
A33: Баланс | B33: =B32+B28 -> 0 | C33: =C32+C28 -> 0 | D33: =D32+D28 -> 69482874 | E33: =E32+E28 -> 85088305 | F33: =F32+F28 -> 85616189 | G33: =G32+G28 -> 93217523 | H33: =H32+H28 -> 94917415 | I33: =I32+I28 -> 0 | ... N33: =N32+N28 -> 0
A35: Изменение активов: | B35: =[1]баланс!$P$38 -> 33798.32 | C35: =C30-C31 -> 0 | D35: =D30-D31 -> 0 | E35: =E30-E31 -> 1196298.1 | F35: =F30-F31 -> 1794907.5 | G35: =G30-G31 -> 2072816.1 | H35: =H30-H31 -> 1651433.6 | I35: =I30-I31 -> -6715455.4 | J35: =J30-J31 -> 0 | ... N35: =N30-N31 -> 0
A38: Справочно:Отчет о фин. рез. "Итоговое изменение активов" | C38: ='Отчет о фин.рез.'!B55 -> 0 | D38: ='Отчет о фин.рез.'!C55 -> 0 | E38: ='Отчет о фин.рез.'!D55 -> 1196.3515 | F38: ='Отчет о фин.рез.'!E55 -> 1794.5871 | G38: ='Отчет о фин.рез.'!F55 -> 2072.8161 | H38: ='Отчет о фин.рез.'!G55 -> 1651.4345 | I38: ='Отчет о фин.рез.'!H55 -> 0 | J38: ='Отчет о фин.рез.'!I55 -> 0 | ... N38: ='Отчет о фин.рез.'!M55 -> 0
A40: Проверка | C40: =+(C38*1000-C35) -> 0 | D40: =+(D38*1000-D35) -> 0 | E40: =+(E38*1000-E35) -> 53.39 | F40: =+(F38*1000-F35) -> -320.44 | G40: =+(G38*1000-G35) -> -0.039999994 | H40: =+(H38*1000-H35) -> 0.91000001 | I40: =+(I38*1000-I35) -> 6715455.4 | J40: =+(J38*1000-J35) -> 0 | ... N40: =+(N38*1000-N35) -> 0
C42: =C32+C27-C14 -> 0 | D42: =D32+D27-D14 -> 1460997.7 | E42: =E32+E27-E14 -> -927117.86 | F42: =F32+F24-F14 -> -78976467 | G42: =G32+G27-G14 -> -6055044.8 | H42: =H32+H27-H14 -> -5695201.2 | I42: =I32+I27-I14 -> 0 | J42: =J32+J27-J14 -> 0 | K42: =K32+K27-K14 -> 0 | L42: =L32+L27-L14 -> 0 | M42: =M32+M27-M14 -> 0 | N42: =N32+N27-N14 -> 0
A45: Имущество баланс | C45: =+SUM(C13:C13)-SUM(B13:B13) -> 0 | D45: =+SUM(D13:D13)-SUM(C13:C13) -> 22609582 | E45: =+SUM(E13:E13)-SUM(D13:D13) -> 3691972.4 | F45: =+SUM(F13:F13)-SUM(E13:E13) -> 539666.88 | G45: =+SUM(G13:G13)-SUM(F13:F13) -> 5007759.5 | H45: =+SUM(H13:H13)-SUM(G13:G13) -> 689747.06 | I45: =+SUM(I13:I13)-SUM(H13:H13) -> -32538728 | J45: =+SUM(J13:J13)-SUM(I13:I13) -> 0 | ... N45: =+SUM(N13:N13)-SUM(M13:M13) -> 0
A46: Имущество фин.рез | C46: ='Отчет о фин.рез.'!B57*1000 -> 0 | D46: ='Отчет о фин.рез.'!C57*1000 -> 22609582 | E46: ='Отчет о фин.рез.'!D57*1000 -> 3691972.4 | F46: ='Отчет о фин.рез.'!E57*1000 -> 539666.88 | G46: ='Отчет о фин.рез.'!F57*1000 -> 5007759.5 | H46: ='Отчет о фин.рез.'!G57*1000 -> 689747.06 | I46: ='Отчет о фин.рез.'!H57*1000 -> 0 | J46: ='Отчет о фин.рез.'!I57*1000 -> 0 | ... N46: ='Отчет о фин.рез.'!M57*1000 -> 0
A47: Проверка | C47: =+C45-C46 -> 0 | D47: =+D45-D46 -> 0 | E47: =+E45-E46 -> 0 | F47: =+F45-F46 -> -9.3132257e-10 | G47: =+G45-G46 -> 0 | H47: =+H45-H46 -> -1.2805685e-09 | I47: =+I45-I46 -> -32538728 | J47: =+J45-J46 -> 0 | ... N47: =+N45-N46 -> 0
...

Sheet Деление БарКухня
E1: 46023 | F1: 46054 | G1: 46082 | H1: 46113 | I1: 46143 | J1: 46174 | K1: 46204 | L1: 46235 | M1: 46266 | N1: 46296 | O1: 46327 | P1: 46357 | Q1: 46388
A2: Бенедикт | B2: Выручка | C2: Зал | D2: Кухня | G2: 3939956 | H2: 9041571.5 | I2: 10579404 | J2: 9819475.4 | Q2: =SUM(E2:P2) -> 33380407
A3: Бенедикт | B3: Выручка | C3: Зал | D3: Бар | G3: 1972289.5 | H3: 4568102.5 | I3: 5094849.5 | J3: 4417617.6 | Q3: =SUM(E3:P3) -> 16052859
A4: Бенедикт | B4: Выручка | C4: Доставка | D4: Кухня | Q4: =SUM(E4:P4) -> 0
A5: Бенедикт | B5: Выручка | C5: Доставка | D5: Бар | Q5: =SUM(E5:P5) -> 0
A6: Бенедикт | B6: Себестоимость | C6: Зал | D6: Кухня | G6: 1152549.8 | H6: 2621768.4 | I6: 3155337.6 | J6: 2945616.7
A7: Бенедикт | B7: Себестоимость | C7: Зал | D7: Бар | G7: 453796.89 | H7: 1056247.5 | I7: 1188078.9 | J7: 1015168
A8: Бенедикт | B8: Себестоимость | C8: Доставка | D8: Кухня
A9: Бенедикт | B9: Себестоимость | C9: Доставка | D9: Бар
A10: Бенедикт | B10: Товарный запас | D10: Кухня | G10: 1001413.6 | H10: 1470765.7 | I10: 1311378.7 | J10: 1180613.8
A11: Бенедикт | B11: Товарный запас | D11: Бар | G11: 1315057.5 | H11: 1497931.5 | I11: 1411650.7 | J11: 1495604.7
A12: Бенедикт | B12: Товарный запас | D12: Склад | G12: 2481.8 | H12: 32451.85 | I12: 0 | J12: 11972.8
A13: Бенедикт | B13: Излишки | D13: Кухня | G13: -27988.17 | H13: -95472.84 | I13: =-(47779.67+51299.47) -> -99079.14 | J13: -98996.95
A14: Бенедикт | B14: Излишки | D14: Бар | G14: -7596.09 | H14: -27430.01 | I14: =-(10368.88+11788.28) -> -22157.16 | J14: -25113.08
A15: Бенедикт | B15: Недостачи | D15: Кухня | G15: 133313.27 | H15: 170319.23 | I15: 157026.42 | J15: 95806.33
A16: Бенедикт | B16: Недостачи | D16: Бар | H16: 12823.04 | I16: 6414.77 | J16: 6283.39
A17: Бенедикт | B17: Излишки, % от себеса | D17: Кухня | E17: =IFERROR(E13/(E6+E8),"-") -> - | F17: =IFERROR(F13/(F6+F8),"-") -> - | G17: =IFERROR(G13/(G6+G8),"-") -> -0.024283696 | H17: =IFERROR(H13/(H6+H8),"-") -> -0.036415436 | I17: =IFERROR(I13/(I6+I8),"-") -> -0.031400488 | J17: =IFERROR(J13/(J6+J8),"-") -> -0.033608225 | K17: =IFERROR(K13/(K6+K8),"-") -> - | L17: =IFERROR(L13/(L6+L8),"-") -> - | ... P17: =IFERROR(P13/(P6+P8),"-") -> -
A18: Бенедикт | B18: Излишки, % от себеса | D18: Бар | E18: =IFERROR(E14/(E7+E9),"-") -> - | F18: =IFERROR(F14/(F7+F9),"-") -> - | G18: =IFERROR(G14/(G7+G9),"-") -> -0.016738964 | H18: =IFERROR(H14/(H7+H9),"-") -> -0.025969303 | I18: =IFERROR(I14/(I7+I9),"-") -> -0.018649569 | J18: =IFERROR(J14/(J7+J9),"-") -> -0.024737855 | K18: =IFERROR(K14/(K7+K9),"-") -> - | L18: =IFERROR(L14/(L7+L9),"-") -> - | ... P18: =IFERROR(P14/(P7+P9),"-") -> -
A19: Бенедикт | B19: Недостачи, % от себеса | D19: Кухня | E19: =IFERROR(E15/(E6+E8),"-") -> - | F19: =IFERROR(F15/(F6+F8),"-") -> - | G19: =IFERROR(G15/(G6+G8),"-") -> 0.11566812 | H19: =IFERROR(H15/(H6+H8),"-") -> 0.064963491 | I19: =IFERROR(I15/(I6+I8),"-") -> 0.049765331 | J19: =IFERROR(J15/(J6+J8),"-") -> 0.03252505 | K19: =IFERROR(K15/(K6+K8),"-") -> - | L19: =IFERROR(L15/(L6+L8),"-") -> - | ... P19: =IFERROR(P15/(P6+P8),"-") -> -
A20: Бенедикт | B20: Недостачи, % от себеса | D20: Бар | E20: =IFERROR(E16/(E7+E9),"-") -> - | F20: =IFERROR(F16/(F7+F9),"-") -> - | G20: =IFERROR(G16/(G7+G9),"-") -> 0 | H20: =IFERROR(H16/(H7+H9),"-") -> 0.012140185 | I20: =IFERROR(I16/(I7+I9),"-") -> 0.0053992793 | J20: =IFERROR(J16/(J7+J9),"-") -> 0.0061895073 | K20: =IFERROR(K16/(K7+K9),"-") -> - | L20: =IFERROR(L16/(L7+L9),"-") -> - | ... P20: =IFERROR(P16/(P7+P9),"-") -> -
A21: Бенедикт | B21: Фудкост | D21: Кухня | E21: =IFERROR((E8+E6)/(E4+E2),"-") -> - | F21: =IFERROR((F8+F6)/(F4+F2),"-") -> - | G21: =IFERROR((G8+G6)/(G4+G2),"-") -> 0.2925286 | H21: =IFERROR((H8+H6)/(H4+H2),"-") -> 0.28996823 | I21: =IFERROR((I8+I6)/(I4+I2),"-") -> 0.29825287 | J21: =IFERROR((J8+J6)/(J4+J2),"-") -> 0.29997699 | K21: =IFERROR((K8+K6)/(K4+K2),"-") -> - | L21: =IFERROR((L8+L6)/(L4+L2),"-") -> - | ... P21: =IFERROR((P8+P6)/(P4+P2),"-") -> -
A22: Бенедикт | B22: Фудкост | D22: Бар | E22: =IFERROR((E9+E7)/(E5+E3),"-") -> - | F22: =IFERROR((F9+F7)/(F5+F3),"-") -> - | G22: =IFERROR((G9+G7)/(G5+G3),"-") -> 0.23008635 | H22: =IFERROR((H9+H7)/(H5+H3),"-") -> 0.23122236 | I22: =IFERROR((I9+I7)/(I5+I3),"-") -> 0.23319216 | J22: =IFERROR((J9+J7)/(J5+J3),"-") -> 0.22979989 | K22: =IFERROR((K9+K7)/(K5+K3),"-") -> - | L22: =IFERROR((L9+L7)/(L5+L3),"-") -> - | ... P22: =IFERROR((P9+P7)/(P5+P3),"-") -> -
B24: проверка Выр | E24: =SUM(E2:E5)-'Отчет о фин.рез.'!B2*1000 -> 0 | F24: =SUM(F2:F5)-'Отчет о фин.рез.'!C2*1000 -> 0 | G24: =SUM(G2:G5)-'Отчет о фин.рез.'!D2*1000 -> -17654.5 | H24: =SUM(H2:H5)-'Отчет о фин.рез.'!E2*1000 -> -103526 | I24: =SUM(I2:I5)-'Отчет о фин.рез.'!F2*1000 -> -38336.5 | J24: =SUM(J2:J5)-'Отчет о фин.рез.'!G2*1000 -> -16258 | K24: =SUM(K2:K5)-'Отчет о фин.рез.'!H2*1000 -> 0 | L24: =SUM(L2:L5)-'Отчет о фин.рез.'!I2*1000 -> 0 | ... P24: =SUM(P2:P5)-'Отчет о фин.рез.'!M2*1000 -> 0
B25: Проверка себес | E25: =SUM(E6:E9)-'Отчет о фин.рез.'!B15*1000 -> 0 | F25: =SUM(F6:F9)-'Отчет о фин.рез.'!C15*1000 -> 0 | G25: =SUM(G6:G9)-'Отчет о фин.рез.'!D15*1000 -> 5785.71 | H25: =SUM(H6:H9)-'Отчет о фин.рез.'!E15*1000 -> -68301.1 | I25: =SUM(I6:I9)-'Отчет о фин.рез.'!F15*1000 -> 146.55 | J25: =SUM(J6:J9)-'Отчет о фин.рез.'!G15*1000 -> 0.75 | K25: =SUM(K6:K9)-'Отчет о фин.рез.'!H15*1000 -> 0 | L25: =SUM(L6:L9)-'Отчет о фин.рез.'!I15*1000 -> 0 | ... P25: =SUM(P6:P9)-'Отчет о фин.рез.'!M15*1000 -> 0
B26: Проверка ТЗ | E26: =SUM(E10:E12)-баланс!C9 -> 0 | F26: =SUM(F10:F12)-баланс!D9 -> -474058.45 | G26: =SUM(G10:G12)-баланс!E9 -> 0 | H26: =SUM(H10:H12)-баланс!F9 -> 0.0099999998 | I26: =SUM(I10:I12)-баланс!G9 -> 338.87 | J26: =SUM(J10:J12)-баланс!H9 -> 339.04 | K26: =SUM(K10:K12)-баланс!I9 -> 0 | L26: =SUM(L10:L12)-баланс!J9 -> 0 | ... P26: =SUM(P10:P12)-баланс!N9 -> 0
B27: Себес | D27: Кухня | E27: =E6+E8 -> 0 | F27: =F6+F8 -> 0 | G27: =G6+G8 -> 1152549.8 | H27: =H6+H8 -> 2621768.4 | I27: =I6+I8 -> 3155337.6 | J27: =J6+J8 -> 2945616.7 | K27: =K6+K8 -> 0 | L27: =L6+L8 -> 0 | ... P27: =P6+P8 -> 0
B28: Наценка | D28: Кухня | E28: =IFERROR((E2+E4)/(E6+E8)-1,"-") -> - | F28: =IFERROR((F2+F4)/(F6+F8)-1,"-") -> - | G28: =IFERROR((G2+G4)/(G6+G8)-1,"-") -> 2.4184691 | H28: =IFERROR((H2+H4)/(H6+H8)-1,"-") -> 2.4486537 | I28: =IFERROR((I2+I4)/(I6+I8)-1,"-") -> 2.3528596 | J28: =IFERROR((J2+J4)/(J6+J8)-1,"-") -> 2.333589 | K28: =IFERROR((K2+K4)/(K6+K8)-1,"-") -> - | L28: =IFERROR((L2+L4)/(L6+L8)-1,"-") -> - | ... P28: =IFERROR((P2+P4)/(P6+P8)-1,"-") -> -
B29: ТЗ | D29: Кухня | E29: =E10 -> 0 | F29: =F10 -> 0 | G29: =G10 -> 1001413.6 | H29: =H10 -> 1470765.7 | I29: =I10 -> 1311378.7 | J29: =J10 -> 1180613.8 | K29: =K10 -> 0 | L29: =L10 -> 0 | ... P29: =P10 -> 0
B30: Оборачиваемость ТЗ | D30: Кухня | E30: =IFERROR(E29/(E27/(F1-E1)),"-") -> - | F30: =IFERROR(F29/(F27/(G1-F1)),"-") -> - | G30: =IFERROR(G29/(G27/(H1-G1)),"-") -> 26.934905 | H30: =IFERROR(H29/(H27/(I1-H1)),"-") -> 16.829469 | I30: =IFERROR(I29/(I27/(J1-I1)),"-") -> 12.8838 | J30: =IFERROR(J29/(J27/(K1-J1)),"-") -> 12.024108 | K30: =IFERROR(K29/(K27/(L1-K1)),"-") -> - | L30: =IFERROR(L29/(L27/(M1-L1)),"-") -> - | ... P30: =IFERROR(P29/(P27/(Q1-P1)),"-") -> -
G31: =IFERROR(SUM(E29:G29)/SUM(E27:G27)*(H1-E1)/3,"-") -> 26.066037 | J31: =IFERROR(SUM(H29:J29)/SUM(H27:J27)*(K1-H1)/3,"-") -> 13.780521 | M31: =IFERROR(SUM(K29:M29)/SUM(K27:M27)*(N1-K1)/3,"-") -> - | P31: =IFERROR(SUM(N29:P29)/SUM(N27:P27)*(Q1-N1)/3,"-") -> -
B33: Себес | D33: Бар | E33: =E9+E7 -> 0 | F33: =F9+F7 -> 0 | G33: =G9+G7 -> 453796.89 | H33: =H9+H7 -> 1056247.5 | I33: =I9+I7 -> 1188078.9 | J33: =J9+J7 -> 1015168 | K33: =K9+K7 -> 0 | L33: =L9+L7 -> 0 | ... P33: =P9+P7 -> 0
B34: Наценка | D34: Бар | E34: =IFERROR((E3+E5)/(E7+E9)-1,"-") -> - | F34: =IFERROR((F3+F5)/(F7+F9)-1,"-") -> - | G34: =IFERROR((G3+G5)/(G7+G9)-1,"-") -> 3.3461944 | H34: =IFERROR((H3+H5)/(H7+H9)-1,"-") -> 3.3248412 | I34: =IFERROR((I3+I5)/(I7+I9)-1,"-") -> 3.2883089 | J34: =IFERROR((J3+J5)/(J7+J9)-1,"-") -> 3.3516122 | K34: =IFERROR((K3+K5)/(K7+K9)-1,"-") -> - | L34: =IFERROR((L3+L5)/(L7+L9)-1,"-") -> - | ... P34: =IFERROR((P3+P5)/(P7+P9)-1,"-") -> -
B35: ТЗ | D35: Бар | E35: =E11 -> 0 | F35: =F11 -> 0 | G35: =G11 -> 1315057.5 | H35: =H11 -> 1497931.5 | I35: =I11 -> 1411650.7 | J35: =J11 -> 1495604.7 | K35: =K11 -> 0 | L35: =L11 -> 0 | ... P35: =P11 -> 0
B36: Оборачиваемость ТЗ | D36: Бар | E36: =IFERROR(E35/(E33/(F1-E1)),"-") -> - | F36: =IFERROR(F35/(F33/(G1-F1)),"-") -> - | G36: =IFERROR(G35/(G33/(H1-G1)),"-") -> 89.834865 | H36: =IFERROR(H35/(H33/(I1-H1)),"-") -> 42.544901 | I36: =IFERROR(I35/(I33/(J1-I1)),"-") -> 36.833556 | J36: =IFERROR(J35/(J33/(K1-J1)),"-") -> 44.197747 | K36: =IFERROR(K35/(K33/(L1-K1)),"-") -> - | L36: =IFERROR(L35/(L33/(M1-L1)),"-") -> - | ... P36: =IFERROR(P35/(P33/(Q1-P1)),"-") -> -
G37: =IFERROR(SUM(E35:G35)/SUM(E33:G33)*(H1-E1)/3,"-") -> 86.936966 | J37: =IFERROR(SUM(H35:J35)/SUM(H33:J33)*(K1-H1)/3,"-") -> 40.995315 | M37: =IFERROR(SUM(K35:M35)/SUM(K33:M33)*(N1-K1)/3,"-") -> - | P37: =IFERROR(SUM(N35:P35)/SUM(N33:P33)*(Q1-N1)/3,"-") -> -
E39: =E1 -> 46023 | F39: =F1 -> 46054 | G39: =G1 -> 46082 | H39: =H1 -> 46113 | I39: =I1 -> 46143 | J39: =J1 -> 46174 | K39: =K1 -> 46204 | L39: =L1 -> 46235 | ... P39: =P1 -> 46357 | Q39: год
B40: Доля в выручке | D40: Бар | E40: =IFERROR(E3/SUM(E2:E3),"-") -> - | F40: =IFERROR(F3/SUM(F2:F3),"-") -> - | G40: =IFERROR(G3/SUM(G2:G3),"-") -> 0.33359398 | H40: =IFERROR(H3/SUM(H2:H3),"-") -> 0.33565113 | I40: =IFERROR(I3/SUM(I2:I3),"-") -> 0.32504575 | J40: =IFERROR(J3/SUM(J2:J3),"-") -> 0.3102893 | K40: =IFERROR(K3/SUM(K2:K3),"-") -> - | L40: =IFERROR(L3/SUM(L2:L3),"-") -> - | ... Q40: =IFERROR(Q3/SUM(Q2:Q3),"-") -> 0.32473798
N46: DjTe3{Q}

Sheet Аналитическая форма
B1: Наименование статей | C1: январь | K1: февраль | S1: март | AA1: апрель | AI1: май | AQ1: июнь | AY1: июль | BG1: август | BO1: сентябрь | BW1: октябрь | CE1: ноябрь | CM1: декабрь | CU1: ГОД
C2: 2025 | E2: 2026 | G2: 2026 | K2: 2025 | M2: 2026 | O2: 2026 | S2: 2025 | U2: 2026 | W2: 2026 | AA2: 2025 | AC2: 2026 | AE2: 2026 | AI2: 2025 | AK2: 2026 | AM2: 2026 | AQ2: 2025 | AS2: 2026 | AU2: 2026 | AY2: 2025 | BA2: 2026 | BC2: 2026 | BG2: 2025 | BI2: 2026 | BK2: 2026 | BO2: 2025 | BQ2: 2026 | BS2: 2026 | BW2: 2025 | BY2: 2026 | CA2: 2026 | CE2: 2025 | CG2: 2026 | CI2: 2026 | CM2: 2025 | CO2: 2026 | CQ2: 2026 | CU2: 2025 | CW2: 2026 | CY2: 2026
C3: факт | D3: доля к Выр, % | E3: план | F3: доля к Выр, % | G3: факт | H3: Доля к Выр, % | I3: Факт/План, % | J3: 26/25, % | K3: факт | L3: доля к Выр, % | M3: план | N3: доля к Выр, % | O3: факт | P3: Доля к Выр, % | Q3: Факт/План, % | R3: 26/25, % | S3: факт | T3: доля к Выр, % | U3: план | V3: доля к Выр, % | W3: факт | X3: Доля к Выр, % | Y3: Факт/План, % | Z3: 26/25, % | AA3: факт | AB3: доля к Выр, % | AC3: план | AD3: доля к Выр, % | AE3: факт | AF3: Доля к Выр, % | AG3: Факт/План, % | AH3: 26/25, % | AI3: факт | AJ3: доля к Выр, % | AK3: план | AL3: доля к Выр, % | AM3: факт | AN3: Доля к Выр, % | AO3: Факт/План, % | AP3: 26/25, % | AQ3: факт | AR3: доля к Выр, % | AS3: план | AT3: доля к Выр, % | AU3: факт | AV3: Доля к Выр, % | AW3: Факт/План, % | AX3: 26/25, % | AY3: факт | AZ3: доля к Выр, % | BA3: план | BB3: доля к Выр, % | BC3: факт | BD3: Доля к Выр, % | BE3: Факт/План, % | BF3: 26/25, % | BG3: факт | BH3: доля к Выр, % | BI3: план | BJ3: доля к Выр, % | BK3: факт | BL3: Доля к Выр, % | BM3: Факт/План, % | BN3: 26/25, % | BO3: факт | BP3: доля к Выр, % | BQ3: план | BR3: доля к Выр, % | BS3: факт | BT3: Доля к Выр, % | BU3: Факт/План, % | BV3: 26/25, % | BW3: факт | BX3: доля к Выр, % | BY3: план | BZ3: доля к Выр, % | CA3: факт | CB3: Доля к Выр, % | CC3: Факт/План, % | CD3: 26/25, % | CE3: факт | CF3: доля к Выр, % | CG3: план | CH3: доля к Выр, % | CI3: факт | CJ3: Доля к Выр, % | CK3: Факт/План, % | CL3: 26/25, % | CM3: факт | CN3: доля к Выр, % | CO3: план | CP3: доля к Выр, % | CQ3: факт | CR3: Доля к Выр, % | CS3: Факт/План, % | CT3: 26/25, % | CU3: факт | CV3: доля к Выр, % | CW3: план | CX3: доля к Выр, % | CY3: факт | CZ3: Доля к Выр, % | DA3: Факт/План, % | DB3: 26/25, %
B4: Выручка, всего, в т.ч. | C4: =SUM(C5:C7) -> 0 | E4: =SUM(E5:E7) -> 0 | G4: =SUM(G5:G7) -> 0 | I4: =IF(IFERROR(G4/E4-1,"")=0,"",IFERROR(+G4/E4-1,"")) | J4: =IF(IFERROR(G4/C4-1,"")=0,"",IFERROR(+G4/C4-1,"")) | K4: =SUM(K5:K7) -> 0 | M4: =SUM(M5:M7) -> 0 | O4: =SUM(O5:O7) -> 0 | Q4: =IF(IFERROR(O4/M4-1,"")=0,"",IFERROR(+O4/M4-1,"")) | R4: =IF(IFERROR(O4/K4-1,"")=0,"",IFERROR(+O4/K4-1,"")) | S4: =SUM(S5:S7) -> 0 | U4: =SUM(U5:U7) -> 0 | W4: =SUM(W5:W7) -> 5929.9 | Y4: =IF(IFERROR(W4/U4-1,"")=0,"",IFERROR(+W4/U4-1,"")) | Z4: =IF(IFERROR(W4/S4-1,"")=0,"",IFERROR(+W4/S4-1,"")) | AA4: =SUM(AA5:AA7) -> 0 | AC4: =SUM(AC5:AC7) -> 13671.84 | AE4: =SUM(AE5:AE7) -> 13713.2 | AG4: =IF(IFERROR(AE4/AC4-1,"")=0,"",IFERROR(+AE4/AC4-1,"")) -> 0.0030251963 | AH4: =IF(IFERROR(AE4/AA4-1,"")=0,"",IFERROR(+AE4/AA4-1,"")) | AI4: =SUM(AI5:AI7) -> 0 | AK4: =SUM(AK5:AK7) -> 13972 | AM4: =SUM(AM5:AM7) -> 15712.59 | AO4: =IF(IFERROR(AM4/AK4-1,"")=0,"",IFERROR(+AM4/AK4-1,"")) -> 0.12457701 | AP4: =IF(IFERROR(AM4/AI4-1,"")=0,"",IFERROR(+AM4/AI4-1,"")) | AQ4: =SUM(AQ5:AQ7) -> 0 | AS4: =SUM(AS5:AS7) -> 15080 | AU4: =SUM(AU5:AU7) -> 14253.351 | AW4: =IF(IFERROR(AU4/AS4-1,"")=0,"",IFERROR(+AU4/AS4-1,"")) -> -0.054817573 | AX4: =IF(IFERROR(AU4/AQ4-1,"")=0,"",IFERROR(+AU4/AQ4-1,"")) | AY4: =SUM(AY5:AY7) -> 0 | BA4: =SUM(BA5:BA7) -> 15667.5 | BC4: =SUM(BC5:BC7) -> 0 | BE4: =IF(IFERROR(BC4/BA4-1,"")=0,"",IFERROR(+BC4/BA4-1,"")) -> -1 | BF4: =IF(IFERROR(BC4/AY4-1,"")=0,"",IFERROR(+BC4/AY4-1,"")) | BG4: =SUM(BG5:BG7) -> 0 | BI4: =SUM(BI5:BI7) -> 15667.5 | BK4: =SUM(BK5:BK7) -> 0 | BM4: =IF(IFERROR(BK4/BI4-1,"")=0,"",IFERROR(+BK4/BI4-1,"")) -> -1 | BN4: =IF(IFERROR(BK4/BG4-1,"")=0,"",IFERROR(+BK4/BG4-1,"")) | BO4: =SUM(BO5:BO7) -> 0 | BQ4: =SUM(BQ5:BQ7) -> 14480 | BS4: =SUM(BS5:BS7) -> 0 | BU4: =IF(IFERROR(BS4/BQ4-1,"")=0,"",IFERROR(+BS4/BQ4-1,"")) -> -1 | BV4: =IF(IFERROR(BS4/BO4-1,"")=0,"",IFERROR(+BS4/BO4-1,"")) | BW4: =SUM(BW5:BW7) -> 0 | BY4: =SUM(BY5:BY7) -> 14084.031 | CA4: =SUM(CA5:CA7) -> 0 | CC4: =IF(IFERROR(CA4/BY4-1,"")=0,"",IFERROR(+CA4/BY4-1,"")) -> -1 | CD4: =IF(IFERROR(CA4/BW4-1,"")=0,"",IFERROR(+CA4/BW4-1,"")) | CE4: =SUM(CE5:CE7) -> 0 | CG4: =SUM(CG5:CG7) -> 14541.024 | CI4: =SUM(CI5:CI7) -> 0 | CK4: =IF(IFERROR(CI4/CG4-1,"")=0,"",IFERROR(+CI4/CG4-1,"")) -> -1 | CL4: =IF(IFERROR(CI4/CE4-1,"")=0,"",IFERROR(+CI4/CE4-1,"")) | CM4: =SUM(CM5:CM7) -> 0 | CO4: =SUM(CO5:CO7) -> 15446.08 | CQ4: =SUM(CQ5:CQ7) -> 0 | CS4: =IF(IFERROR(CQ4/CO4-1,"")=0,"",IFERROR(+CQ4/CO4-1,"")) -> -1 | CT4: =IF(IFERROR(CQ4/CM4-1,"")=0,"",IFERROR(+CQ4/CM4-1,"")) | CU4: =SUM(C4,K4,S4,AA4,AI4,AQ4,AY4,BG4,BO4,BW4,CE4,CM4) -> 0 | CV4: =IFERROR(CU4/CU$4,"") | CW4: =SUM(E4,M4,U4,AC4,AK4,AS4,BA4,BI4,BQ4,BY4,CG4,CO4) -> 132609.98 | CX4: =IFERROR(CW4/CW$4,"") -> 1 | CY4: =SUM(G4,O4,W4,AE4,AM4,AU4,BC4,BK4,BS4,CA4,CI4,CQ4) -> 49609.041 | CZ4: =IFERROR(CY4/CY$4,"") -> 1 | DA4: =IF(IFERROR(CY4/CW4-1,"")=0,"",IFERROR(+CY4/CW4-1,"")) -> -0.62590265 | DB4: =IF(IFERROR(CY4/CU4-1,"")=0,"",IFERROR(+CY4/CU4-1,""))
B5: зал | D5: =IFERROR(C5/C$4,".") -> . | F5: =IFERROR(E5/E$4,"") | G5: =+'Отчет о фин.рез.'!B3 -> 0 | H5: =IFERROR(G5/G$4,"") | I5: =IF(IFERROR(G5/E5-1,"")=0,"",IFERROR(+G5/E5-1,"")) | J5: =IF(IFERROR(G5/C5-1,"")=0,"",IFERROR(+G5/C5-1,"")) | L5: =IFERROR(K5/K$4,".") -> . | N5: =IFERROR(M5/M$4,"") | O5: =+'Отчет о фин.рез.'!C3 -> 0 | P5: =IFERROR(O5/O$4,"") | Q5: =IF(IFERROR(O5/M5-1,"")=0,"",IFERROR(+O5/M5-1,"")) | R5: =IF(IFERROR(O5/K5-1,"")=0,"",IFERROR(+O5/K5-1,"")) | T5: =IFERROR(S5/S$4,".") -> . | U5: 0 | V5: =IFERROR(U5/U$4,"") | W5: =+'Отчет о фин.рез.'!D3 -> 5929.9 | X5: =IFERROR(W5/W$4,"") -> 1 | Y5: =IF(IFERROR(W5/U5-1,"")=0,"",IFERROR(+W5/U5-1,"")) | Z5: =IF(IFERROR(W5/S5-1,"")=0,"",IFERROR(+W5/S5-1,"")) | AB5: =IFERROR(AA5/AA$4,".") -> . | AC5: 13671.84 | AD5: =IFERROR(AC5/AC$4,"") -> 1 | AE5: =+'Отчет о фин.рез.'!E3 -> 13713.2 | AF5: =IFERROR(AE5/AE$4,"") -> 1 | AG5: =IF(IFERROR(AE5/AC5-1,"")=0,"",IFERROR(+AE5/AC5-1,"")) -> 0.0030251963 | AH5: =IF(IFERROR(AE5/AA5-1,"")=0,"",IFERROR(+AE5/AA5-1,"")) | AJ5: =IFERROR(AI5/AI$4,".") -> . | AK5: 13672 | AL5: =IFERROR(AK5/AK$4,"") -> 0.97852849 | AM5: =+'Отчет о фин.рез.'!F3 -> 15712.59 | AN5: =IFERROR(AM5/AM$4,"") -> 1 | AO5: =IF(IFERROR(AM5/AK5-1,"")=0,"",IFERROR(+AM5/AK5-1,"")) -> 0.14925322 | AP5: =IF(IFERROR(AM5/AI5-1,"")=0,"",IFERROR(+AM5/AI5-1,"")) | AR5: =IFERROR(AQ5/AQ$4,".") -> . | AS5: 14960 | AT5: =IFERROR(AS5/AS$4,"") -> 0.99204244 | AU5: =+'Отчет о фин.рез.'!G3 -> 14253.351 | AV5: =IFERROR(AU5/AU$4,"") -> 1 | AW5: =IF(IFERROR(AU5/AS5-1,"")=0,"",IFERROR(+AU5/AS5-1,"")) -> -0.047235896 | AX5: =IF(IFERROR(AU5/AQ5-1,"")=0,"",IFERROR(+AU5/AQ5-1,"")) | AZ5: =IFERROR(AY5/AY$4,".") -> . | BA5: 15487.5 | BB5: =IFERROR(BA5/BA$4,"") -> 0.98851125 | BC5: =+'Отчет о фин.рез.'!H3 -> 0 | BD5: =IFERROR(BC5/BC$4,"") | BE5: =IF(IFERROR(BC5/BA5-1,"")=0,"",IFERROR(+BC5/BA5-1,"")) -> -1 | BF5: =IF(IFERROR(BC5/AY5-1,"")=0,"",IFERROR(+BC5/AY5-1,"")) | BH5: =IFERROR(BG5/BG$4,".") -> . | BI5: 15487.5 | BJ5: =IFERROR(BI5/BI$4,"") -> 0.98851125 | BK5: =+'Отчет о фин.рез.'!I3 -> 0 | BL5: =IFERROR(BK5/BK$4,"") | BM5: =IF(IFERROR(BK5/BI5-1,"")=0,"",IFERROR(+BK5/BI5-1,"")) -> -1 | BN5: =IF(IFERROR(BK5/BG5-1,"")=0,"",IFERROR(+BK5/BG5-1,"")) | BP5: =IFERROR(BO5/BO$4,".") -> . | BQ5: 14280 | BR5: =IFERROR(BQ5/BQ$4,"") -> 0.98618785 | BS5: =+'Отчет о фин.рез.'!J3 -> 0 | BT5: =IFERROR(BS5/BS$4,"") | BU5: =IF(IFERROR(BS5/BQ5-1,"")=0,"",IFERROR(+BS5/BQ5-1,"")) -> -1 | BV5: =IF(IFERROR(BS5/BO5-1,"")=0,"",IFERROR(+BS5/BO5-1,"")) | BX5: =IFERROR(BW5/BW$4,".") -> . | BY5: 10385.957 | BZ5: =IFERROR(BY5/BY$4,"") -> 0.73742788 | CA5: =+'Отчет о фин.рез.'!K3 -> 0 | CB5: =IFERROR(CA5/CA$4,"") | CC5: =IF(IFERROR(CA5/BY5-1,"")=0,"",IFERROR(+CA5/BY5-1,"")) -> -1 | CD5: =IF(IFERROR(CA5/BW5-1,"")=0,"",IFERROR(+CA5/BW5-1,"")) | CF5: =IFERROR(CE5/CE$4,".") -> . | CG5: 11111.833 | CH5: =IFERROR(CG5/CG$4,"") -> 0.76417124 | CI5: =+'Отчет о фин.рез.'!L3 -> 0 | CJ5: =IFERROR(CI5/CI$4,"") | CK5: =IF(IFERROR(CI5/CG5-1,"")=0,"",IFERROR(+CI5/CG5-1,"")) -> -1 | CL5: =IF(IFERROR(CI5/CE5-1,"")=0,"",IFERROR(+CI5/CE5-1,"")) | CN5: =IFERROR(CM5/CM$4,".") -> . | CO5: 11288.099 | CP5: =IFERROR(CO5/CO$4,"") -> 0.73080672 | CQ5: =+'Отчет о фин.рез.'!M3 -> 0 | CR5: =IFERROR(CQ5/CQ$4,"") | CS5: =IF(IFERROR(CQ5/CO5-1,"")=0,"",IFERROR(+CQ5/CO5-1,"")) -> -1 | CT5: =IF(IFERROR(CQ5/CM5-1,"")=0,"",IFERROR(+CQ5/CM5-1,"")) | CU5: =SUM(C5,K5,S5,AA5,AI5,AQ5,AY5,BG5,BO5,BW5,CE5,CM5) -> 0 | CV5: =IFERROR(CU5/CU$4,"") | CW5: =SUM(E5,M5,U5,AC5,AK5,AS5,BA5,BI5,BQ5,BY5,CG5,CO5) -> 120344.73 | CX5: =IFERROR(CW5/CW$4,"") -> 0.90750887 | CY5: =SUM(G5,O5,W5,AE5,AM5,AU5,BC5,BK5,BS5,CA5,CI5,CQ5) -> 49609.041 | CZ5: =IFERROR(CY5/CY$4,"") -> 1 | DA5: =IF(IFERROR(CY5/CW5-1,"")=0,"",IFERROR(+CY5/CW5-1,"")) -> -0.58777554 | DB5: =IF(IFERROR(CY5/CU5-1,"")=0,"",IFERROR(+CY5/CU5-1,""))
B6: доставка | D6: =IFERROR(C6/C$4,"") | F6: =IFERROR(E6/E$4,"") | G6: =+'Отчет о фин.рез.'!B4 -> 0 | H6: =IFERROR(G6/G$4,"") | I6: =IF(IFERROR(G6/E6-1,"")=0,"",IFERROR(+G6/E6-1,"")) | J6: =IF(IFERROR(G6/C6-1,"")=0,"",IFERROR(+G6/C6-1,"")) | L6: =IFERROR(K6/K$4,"") | N6: =IFERROR(M6/M$4,"") | O6: =+'Отчет о фин.рез.'!C4 -> 0 | P6: =IFERROR(O6/O$4,"") | Q6: =IF(IFERROR(O6/M6-1,"")=0,"",IFERROR(+O6/M6-1,"")) | R6: =IF(IFERROR(O6/K6-1,"")=0,"",IFERROR(+O6/K6-1,"")) | T6: =IFERROR(S6/S$4,"") | U6: 0 | V6: =IFERROR(U6/U$4,"") | W6: =+'Отчет о фин.рез.'!D4 -> 0 | X6: =IFERROR(W6/W$4,"") -> 0 | Y6: =IF(IFERROR(W6/U6-1,"")=0,"",IFERROR(+W6/U6-1,"")) | Z6: =IF(IFERROR(W6/S6-1,"")=0,"",IFERROR(+W6/S6-1,"")) | AB6: =IFERROR(AA6/AA$4,"") | AC6: 0 | AD6: =IFERROR(AC6/AC$4,"") -> 0 | AE6: =+'Отчет о фин.рез.'!E4 -> 0 | AF6: =IFERROR(AE6/AE$4,"") -> 0 | AG6: =IF(IFERROR(AE6/AC6-1,"")=0,"",IFERROR(+AE6/AC6-1,"")) | AH6: =IF(IFERROR(AE6/AA6-1,"")=0,"",IFERROR(+AE6/AA6-1,"")) | AJ6: =IFERROR(AI6/AI$4,"") | AK6: 300 | AL6: =IFERROR(AK6/AK$4,"") -> 0.021471514 | AM6: =+'Отчет о фин.рез.'!F4 -> 0 | AN6: =IFERROR(AM6/AM$4,"") -> 0 | AO6: =IF(IFERROR(AM6/AK6-1,"")=0,"",IFERROR(+AM6/AK6-1,"")) -> -1 | AP6: =IF(IFERROR(AM6/AI6-1,"")=0,"",IFERROR(+AM6/AI6-1,"")) | AR6: =IFERROR(AQ6/AQ$4,"") | AS6: 120 | AT6: =IFERROR(AS6/AS$4,"") -> 0.0079575597 | AU6: =+'Отчет о фин.рез.'!G4 -> 0 | AV6: =IFERROR(AU6/AU$4,"") -> 0 | AW6: =IF(IFERROR(AU6/AS6-1,"")=0,"",IFERROR(+AU6/AS6-1,"")) -> -1 | AX6: =IF(IFERROR(AU6/AQ6-1,"")=0,"",IFERROR(+AU6/AQ6-1,"")) | AZ6: =IFERROR(AY6/AY$4,"") | BA6: 180 | BB6: =IFERROR(BA6/BA$4,"") -> 0.011488751 | BC6: =+'Отчет о фин.рез.'!H4 -> 0 | BD6: =IFERROR(BC6/BC$4,"") | BE6: =IF(IFERROR(BC6/BA6-1,"")=0,"",IFERROR(+BC6/BA6-1,"")) -> -1 | BF6: =IF(IFERROR(BC6/AY6-1,"")=0,"",IFERROR(+BC6/AY6-1,"")) | BH6: =IFERROR(BG6/BG$4,"") | BI6: 180 | BJ6: =IFERROR(BI6/BI$4,"") -> 0.011488751 | BK6: =+'Отчет о фин.рез.'!I4 -> 0 | BL6: =IFERROR(BK6/BK$4,"") | BM6: =IF(IFERROR(BK6/BI6-1,"")=0,"",IFERROR(+BK6/BI6-1,"")) -> -1 | BN6: =IF(IFERROR(BK6/BG6-1,"")=0,"",IFERROR(+BK6/BG6-1,"")) | BP6: =IFERROR(BO6/BO$4,"") | BQ6: 200 | BR6: =IFERROR(BQ6/BQ$4,"") -> 0.013812155 | BS6: =+'Отчет о фин.рез.'!J4 -> 0 | BT6: =IFERROR(BS6/BS$4,"") | BU6: =IF(IFERROR(BS6/BQ6-1,"")=0,"",IFERROR(+BS6/BQ6-1,"")) -> -1 | BV6: =IF(IFERROR(BS6/BO6-1,"")=0,"",IFERROR(+BS6/BO6-1,"")) | BX6: =IFERROR(BW6/BW$4,"") | BY6: 3698.0738 | BZ6: =IFERROR(BY6/BY$4,"") -> 0.26257212 | CA6: =+'Отчет о фин.рез.'!K4 -> 0 | CB6: =IFERROR(CA6/CA$4,"") | CC6: =IF(IFERROR(CA6/BY6-1,"")=0,"",IFERROR(+CA6/BY6-1,"")) -> -1 | CD6: =IF(IFERROR(CA6/BW6-1,"")=0,"",IFERROR(+CA6/BW6-1,"")) | CF6: =IFERROR(CE6/CE$4,"") | CG6: 3429.1918 | CH6: =IFERROR(CG6/CG$4,"") -> 0.23582876 | CI6: =+'Отчет о фин.рез.'!L4 -> 0 | CJ6: =IFERROR(CI6/CI$4,"") | CK6: =IF(IFERROR(CI6/CG6-1,"")=0,"",IFERROR(+CI6/CG6-1,"")) -> -1 | CL6: =IF(IFERROR(CI6/CE6-1,"")=0,"",IFERROR(+CI6/CE6-1,"")) | CN6: =IFERROR(CM6/CM$4,"") | CO6: 4157.9811 | CP6: =IFERROR(CO6/CO$4,"") -> 0.26919328 | CQ6: =+'Отчет о фин.рез.'!M4 -> 0 | CR6: =IFERROR(CQ6/CQ$4,"") | CS6: =IF(IFERROR(CQ6/CO6-1,"")=0,"",IFERROR(+CQ6/CO6-1,"")) -> -1 | CT6: =IF(IFERROR(CQ6/CM6-1,"")=0,"",IFERROR(+CQ6/CM6-1,"")) | CU6: =SUM(C6,K6,S6,AA6,AI6,AQ6,AY6,BG6,BO6,BW6,CE6,CM6) -> 0 | CV6: =IFERROR(CU6/CU$4,"") | CW6: =SUM(E6,M6,U6,AC6,AK6,AS6,BA6,BI6,BQ6,BY6,CG6,CO6) -> 12265.247 | CX6: =IFERROR(CW6/CW$4,"") -> 0.092491132 | CY6: =SUM(G6,O6,W6,AE6,AM6,AU6,BC6,BK6,BS6,CA6,CI6,CQ6) -> 0 | CZ6: =IFERROR(CY6/CY$4,"") -> 0 | DA6: =IF(IFERROR(CY6/CW6-1,"")=0,"",IFERROR(+CY6/CW6-1,"")) -> -1 | DB6: =IF(IFERROR(CY6/CU6-1,"")=0,"",IFERROR(+CY6/CU6-1,""))
B7: Доп подразделение (назвать по-своему или пустое) | D7: =IFERROR(C7/C$4,"") | F7: =IFERROR(E7/E$4,"") | G7: =+'Отчет о фин.рез.'!B5 -> 0 | H7: =IFERROR(G7/G$4,"") | I7: =IF(IFERROR(G7/E7-1,"")=0,"",IFERROR(+G7/E7-1,"")) | J7: =IF(IFERROR(G7/C7-1,"")=0,"",IFERROR(+G7/C7-1,"")) | L7: =IFERROR(K7/K$4,"") | N7: =IFERROR(M7/M$4,"") | O7: =+'Отчет о фин.рез.'!C5 -> 0 | P7: =IFERROR(O7/O$4,"") | Q7: =IF(IFERROR(O7/M7-1,"")=0,"",IFERROR(+O7/M7-1,"")) | R7: =IF(IFERROR(O7/K7-1,"")=0,"",IFERROR(+O7/K7-1,"")) | T7: =IFERROR(S7/S$4,"") | U7: 0 | V7: =IFERROR(U7/U$4,"") | W7: =+'Отчет о фин.рез.'!D5 -> 0 | X7: =IFERROR(W7/W$4,"") -> 0 | Y7: =IF(IFERROR(W7/U7-1,"")=0,"",IFERROR(+W7/U7-1,"")) | Z7: =IF(IFERROR(W7/S7-1,"")=0,"",IFERROR(+W7/S7-1,"")) | AB7: =IFERROR(AA7/AA$4,"") | AC7: 0 | AD7: =IFERROR(AC7/AC$4,"") -> 0 | AE7: =+'Отчет о фин.рез.'!E5 -> 0 | AF7: =IFERROR(AE7/AE$4,"") -> 0 | AG7: =IF(IFERROR(AE7/AC7-1,"")=0,"",IFERROR(+AE7/AC7-1,"")) | AH7: =IF(IFERROR(AE7/AA7-1,"")=0,"",IFERROR(+AE7/AA7-1,"")) | AJ7: =IFERROR(AI7/AI$4,"") | AK7: 0 | AL7: =IFERROR(AK7/AK$4,"") -> 0 | AM7: =+'Отчет о фин.рез.'!F5 -> 0 | AN7: =IFERROR(AM7/AM$4,"") -> 0 | AO7: =IF(IFERROR(AM7/AK7-1,"")=0,"",IFERROR(+AM7/AK7-1,"")) | AP7: =IF(IFERROR(AM7/AI7-1,"")=0,"",IFERROR(+AM7/AI7-1,"")) | AR7: =IFERROR(AQ7/AQ$4,"") | AS7: 0 | AT7: =IFERROR(AS7/AS$4,"") -> 0 | AU7: =+'Отчет о фин.рез.'!G5 -> 0 | AV7: =IFERROR(AU7/AU$4,"") -> 0 | AW7: =IF(IFERROR(AU7/AS7-1,"")=0,"",IFERROR(+AU7/AS7-1,"")) | AX7: =IF(IFERROR(AU7/AQ7-1,"")=0,"",IFERROR(+AU7/AQ7-1,"")) | AZ7: =IFERROR(AY7/AY$4,"") | BA7: 0 | BB7: =IFERROR(BA7/BA$4,"") -> 0 | BC7: =+'Отчет о фин.рез.'!H5 -> 0 | BD7: =IFERROR(BC7/BC$4,"") | BE7: =IF(IFERROR(BC7/BA7-1,"")=0,"",IFERROR(+BC7/BA7-1,"")) | BF7: =IF(IFERROR(BC7/AY7-1,"")=0,"",IFERROR(+BC7/AY7-1,"")) | BH7: =IFERROR(BG7/BG$4,"") | BI7: 0 | BJ7: =IFERROR(BI7/BI$4,"") -> 0 | BK7: =+'Отчет о фин.рез.'!I5 -> 0 | BL7: =IFERROR(BK7/BK$4,"") | BM7: =IF(IFERROR(BK7/BI7-1,"")=0,"",IFERROR(+BK7/BI7-1,"")) | BN7: =IF(IFERROR(BK7/BG7-1,"")=0,"",IFERROR(+BK7/BG7-1,"")) | BP7: =IFERROR(BO7/BO$4,"") | BQ7: 0 | BR7: =IFERROR(BQ7/BQ$4,"") -> 0 | BS7: =+'Отчет о фин.рез.'!J5 -> 0 | BT7: =IFERROR(BS7/BS$4,"") | BU7: =IF(IFERROR(BS7/BQ7-1,"")=0,"",IFERROR(+BS7/BQ7-1,"")) | BV7: =IF(IFERROR(BS7/BO7-1,"")=0,"",IFERROR(+BS7/BO7-1,"")) | BX7: =IFERROR(BW7/BW$4,"") | BY7: 0 | BZ7: =IFERROR(BY7/BY$4,"") -> 0 | CA7: =+'Отчет о фин.рез.'!K5 -> 0 | CB7: =IFERROR(CA7/CA$4,"") | CC7: =IF(IFERROR(CA7/BY7-1,"")=0,"",IFERROR(+CA7/BY7-1,"")) | CD7: =IF(IFERROR(CA7/BW7-1,"")=0,"",IFERROR(+CA7/BW7-1,"")) | CF7: =IFERROR(CE7/CE$4,"") | CG7: 0 | CH7: =IFERROR(CG7/CG$4,"") -> 0 | CI7: =+'Отчет о фин.рез.'!L5 -> 0 | CJ7: =IFERROR(CI7/CI$4,"") | CK7: =IF(IFERROR(CI7/CG7-1,"")=0,"",IFERROR(+CI7/CG7-1,"")) | CL7: =IF(IFERROR(CI7/CE7-1,"")=0,"",IFERROR(+CI7/CE7-1,"")) | CN7: =IFERROR(CM7/CM$4,"") | CO7: 0 | CP7: =IFERROR(CO7/CO$4,"") -> 0 | CQ7: =+'Отчет о фин.рез.'!M5 -> 0 | CR7: =IFERROR(CQ7/CQ$4,"") | CS7: =IF(IFERROR(CQ7/CO7-1,"")=0,"",IFERROR(+CQ7/CO7-1,"")) | CT7: =IF(IFERROR(CQ7/CM7-1,"")=0,"",IFERROR(+CQ7/CM7-1,"")) | CU7: =SUM(C7,K7,S7,AA7,AI7,AQ7,AY7,BG7,BO7,BW7,CE7,CM7) -> 0 | CV7: =IFERROR(CU7/CU$4,"") | CW7: =SUM(E7,M7,U7,AC7,AK7,AS7,BA7,BI7,BQ7,BY7,CG7,CO7) -> 0 | CX7: =IFERROR(CW7/CW$4,"") -> 0 | CY7: =SUM(G7,O7,W7,AE7,AM7,AU7,BC7,BK7,BS7,CA7,CI7,CQ7) -> 0 | CZ7: =IFERROR(CY7/CY$4,"") -> 0 | DA7: =IF(IFERROR(CY7/CW7-1,"")=0,"",IFERROR(+CY7/CW7-1,"")) | DB7: =IF(IFERROR(CY7/CU7-1,"")=0,"",IFERROR(+CY7/CU7-1,""))
